Workbook

Sheet 00_Index
A1: AAH Financial Statement Format Library — Final Preparation Baseline
A3: No. | B3: Code | C3: Profile | D3: Authority | E3: Face Statements | F3: Notes / Schedules | G3: Special Statements | H3: AAH Mapping Ready
A4: 1 | B4: C_AS | C4: Company — AS — Schedule III Division I | D4: MCA | E4: Balance Sheet + P&L / equivalent | F4: Detailed linked note lines | G4: — | H4: Yes
A5: 2 | B5: C_IND | C5: Company — Ind AS — Schedule III Division II | D5: MCA | E5: Balance Sheet + P&L / equivalent | F5: Detailed linked note lines | G5: Statement of Changes in Equity, Cash Flow Statement | H5: Yes
A6: 3 | B6: NBFC_AS | C6: NBFC — Accounting Standards (non-Ind AS) | D6: MCA + RBI | E6: Balance Sheet + P&L / equivalent | F6: Detailed linked note lines | G6: RBI Regulatory Disclosure Pack | H6: Yes
A7: 4 | B7: NBFC_IND | C7: NBFC — Ind AS — Schedule III Division III | D7: MCA + RBI | E7: Balance Sheet + P&L / equivalent | F7: Detailed linked note lines | G7: Statement of Changes in Equity, Cash Flow Statement, RBI Regulatory Disclosure Pack | H7: Yes
A8: 5 | B8: NCE | C8: Non-Corporate Entity | D8: ICAI | E8: Balance Sheet + P&L / equivalent | F8: Detailed linked note lines | G8: Cash Flow Statement where applicable | H8: Yes
A9: 6 | B9: LLP | C9: Limited Liability Partnership | D9: ICAI + MCA | E9: Balance Sheet + P&L / equivalent | F9: Detailed linked note lines | G9: Cash Flow Statement where applicable, MCA Form 8 support output | H9: Yes
A10: 7 | B10: NPO | C10: Not-for-Profit Organisation | D10: ICAI / governing statute | E10: Balance Sheet + P&L / equivalent | F10: Detailed linked note lines | G10: Receipts & Payments where required, Fund movement schedules | H10: Yes
A11: 8 | B11: BANK | C11: Banking Company | D11: RBI / Banking Regulation Act | E11: Balance Sheet + P&L / equivalent | F11: Detailed linked note lines | G11: Form A Balance Sheet, Form B P&L, Schedules 1-16 | H11: Yes
A12: 9 | B12: COOPBANK | C12: Co-operative Bank | D12: RBI / Banking Regulation Act as adapted | E12: Balance Sheet + P&L / equivalent | F12: Detailed linked note lines | G12: Co-operative-bank adapted schedules, Overdue Interest Reserve disclosure | H12: Yes
A13: 10 | B13: LIFE | C13: Life Insurance | D13: IRDAI | E13: Balance Sheet + P&L / equivalent | F13: Detailed linked note lines | G13: Form A-BS, Form A-RA, Form A-PL | H13: Yes
A14: 11 | B14: GENINS | C14: General Insurance | D14: IRDAI | E14: Balance Sheet + P&L / equivalent | F14: Detailed linked note lines | G14: Form B-BS, Form B-RA, Form B-PL | H14: Yes
A15: 12 | B15: REINS | C15: Reinsurance | D15: IRDAI | E15: Balance Sheet + P&L / equivalent | F15: Detailed linked note lines | G15: Reinsurance-specific B-series forms, Regulatory reserve disclosures | H15: Yes
... A19: 16 | B19: INVIT | C19: Infrastructure Investment Trust | D19: SEBI | E19: Balance Sheet + P&L / equivalent | F19: Detailed linked note lines | G19: Statement of Changes in Unitholders' Equity, Cash Flow Statement, Statement of Net Assets at Fair Value, Statement of Total Returns at Fair Value, NDCF / Distribution Statement | H19: Yes

Sheet 01_Workflow
A1: Standard Financial Statement Preparation Workflow
A3: Step | B3: Stage | C3: What happens | D3: AAH authority | E3: User role | F3: Output
A4: 1 | B4: Profile | C4: Select legal/accounting/regulatory profile | D4: Client + FY | E4: Confirm | F4: Correct statutory schema
A5: 2 | B5: Data authority | C5: Bring current + comparative ledger balances | D5: AAH/Tally sync | E5: Review only | F5: Trial balance authority
A6: 3 | B6: Mapping | C6: Map ledger/group to AAH Mapping Key | D6: Persistent by MasterId | E6: Resolve unmapped | F6: Note allocation
A7: 4 | B7: Disclosures | C7: Capture non-ledger facts / statutory tables | D7: Client + FY | E7: Enter/approve | F7: Supplementary disclosure authority
A8: 5 | B8: Notes | C8: Aggregate mapping keys into note lines | D8: Calculated | E8: Review | F8: Complete Notes
A9: 6 | B9: Face statements | C9: Notes feed BS/P&L/I&E/Revenue Account | D9: Calculated | E9: None | F9: Final statements
A10: 7 | B10: Special statements | C10: CFS/SOCE/NAV/NDCF/regulatory schedules | D10: Calculated | E10: Review | F10: Complete report set
A11: 8 | B11: Validation | C11: Tie-outs, balance, mapping completeness, comparatives | D11: Calculated | E11: Resolve failures | F11: Ready status
A12: 9 | B12: Print pack | C12: Only clean final statements and notes | D12: Calculated | E12: Export / sign | F12: Excel/PDF-ready pack
A13: 10 | B13: Year rollover | C13: Carry mapping, not manual amounts | D13: AAH | E13: Review changes | F13: Next-year comparative setup

Sheet 02_Sources
A1: Official Source Register
A3: Profile | B3: Authority | C3: Official URL | D3: Rule
A4: Company — AS — Schedule III Division I | B4: MCA | C4: https://www.mca.gov.in/Ministry/pdf/ScheduleIIIAmendmentNotification_24032021.pdf | D4: Specific regulator/statute presentation overrides a generic format.
A5: Company — Ind AS — Schedule III Division II | B5: MCA | C5: https://www.mca.gov.in/Ministry/pdf/ScheduleIIIAmendmentNotification_24032021.pdf | D5: Specific regulator/statute presentation overrides a generic format.
A6: NBFC — Accounting Standards (non-Ind AS) | B6: MCA + RBI | C6: https://www.rbi.org.in/ | D6: Specific regulator/statute presentation overrides a generic format.
A7: NBFC — Ind AS — Schedule III Division III | B7: MCA + RBI | C7: https://www.mca.gov.in/Ministry/pdf/NotificationScheduleIII_12102018.pdf | D7: Specific regulator/statute presentation overrides a generic format.
A8: Non-Corporate Entity | B8: ICAI | C8: https://www.icai.org/post/guidance-notes | D8: Specific regulator/statute presentation overrides a generic format.
A9: Limited Liability Partnership | B9: ICAI + MCA | C9: https://www.icai.org/post/guidance-notes | D9: Specific regulator/statute presentation overrides a generic format.
A10: Not-for-Profit Organisation | B10: ICAI / governing statute | C10: https://www.icai.org/post/technical-guides-and-other-materials | D10: Specific regulator/statute presentation overrides a generic format.
A11: Banking Company | B11: RBI / Banking Regulation Act | C11: https://www.indiacode.nic.in/bitstream/123456789/1885/1/A194910.pdf | D11: Specific regulator/statute presentation overrides a generic format.
A12: Co-operative Bank | B12: RBI / Banking Regulation Act as adapted | C12: https://www.rbi.org.in/ | D12: Specific regulator/statute presentation overrides a generic format.
A13: Life Insurance | B13: IRDAI | C13: https://irdai.gov.in/ | D13: Specific regulator/statute presentation overrides a generic format.
A14: General Insurance | B14: IRDAI | C14: https://irdai.gov.in/ | D14: Specific regulator/statute presentation overrides a generic format.
... A19: Infrastructure Investment Trust | B19: SEBI | C19: https://www.sebi.gov.in/sebi_data/attachdocs/jul-2025/1752576381910.pdf | D19: Specific regulator/statute presentation overrides a generic format.

Sheet C_AS
A1: Company — AS — Schedule III Division I
A2: Authority: MCA | Official source: https://www.mca.gov.in/Ministry/pdf/ScheduleIIIAmendmentNotification_24032021.pdf
A3: =IF('AAH Basic Info'!B5="","","Address: "&'AAH Basic Info'!B5) | B3: =IF('AAH Basic Info'!B6="","","PAN: "&'AAH Basic Info'!B6) | C3: =IF('AAH Basic Info'!B7="","","GSTIN: "&'AAH Basic Info'!B7) | D3: =IF('AAH Basic Info'!B27="","",'AAH Basic Info'!B27)
A4: Entity Name | B4: Current Period | C4: Previous Period | D4: Presentation Unit | E4: Standalone / Consolidated
A5: =IF('AAH Basic Info'!B3="","",'AAH Basic Info'!B3) | B5: =IF('AAH Basic Info'!B9="","",'AAH Basic Info'!B9) | C5: =IF('AAH Basic Info'!B10="","",'AAH Basic Info'!B10) | D5: =IF('AAH Basic Info'!B24="","",'AAH Basic Info'!B24) | E5: =IF('AAH Basic Info'!B25="","",'AAH Basic Info'!B25)
A6: Balance Sheet / Statement of Financial Position
A7: Particulars | B7: Note No. | C7: Current Reporting Period | D7: Previous Reporting Period
A8: EQUITY AND LIABILITIES
A9: 1. Shareholders' Funds
A10: Share Capital | B10: 1 | C10: =E75 | D10: =F75
A11: Reserves and Surplus | B11: 2 | C11: =E83 | D11: =F83
A12: 2. Share Application Money Pending Allotment
A13: Share Application Money Pending Allotment | B13: —
A14: 3. Non-current Liabilities
A15: Long-term Borrowings | B15: 3 | C15: =E92 | D15: =F92
A16: Deferred Tax Liabilities (Net) | B16: 4 | C16: =E94 | D16: =F94
A17: Other Long-term Liabilities | B17: 5 | C17: =E98 | D17: =F98
A18: Long-term Provisions | B18: 6 | C18: =E101 | D18: =F101
A19: 4. Current Liabilities
A20: Short-term Borrowings | B20: 7 | C20: =E107 | D20: =F107
A21: Trade Payables | B21: 8 | C21: =E112 | D21: =F112
A22: Other Current Liabilities | B22: 9 | C22: =E121 | D22: =F121
A23: Short-term Provisions | B23: 10 | C23: =E125 | D23: =F125
A24: TOTAL EQUITY AND LIABILITIES | C24: =SUM(C10,C11,C13,C15,C16,C17,C18,C20,C21,C22,C23) | D24: =SUM(D10,D11,D13,D15,D16,D17,D18,D20,D21,D22,D23)
A25: ASSETS
A26: 1. Non-current Assets
A27: Property, Plant and Equipment / Intangibles / CWIP | B27: 11 | C27: =E135 | D27: =F135
A28: Non-current Investments | B28: 12 | C28: =E144 | D28: =F144
A29: Deferred Tax Assets (Net) | B29: 4 | C29: =E93 | D29: =F93
A30: Long-term Loans and Advances | B30: 13 | C30: =E150 | D30: =F150
A31: Other Non-current Assets | B31: 14 | C31: =E154 | D31: =F154
A32: 2. Current Assets
A33: Current Investments | B33: 15 | C33: =E158 | D33: =F158
A34: Inventories | B34: 16 | C34: =E167 | D34: =F167
A35: Trade Receivables | B35: 17 | C35: =E173 | D35: =F173
A36: Cash and Cash Equivalents | B36: 18 | C36: =E178 | D36: =F178
A37: Short-term Loans and Advances | B37: 19 | C37: =E182 | D37: =F182
A38: Other Current Assets | B38: 20 | C38: =E187 | D38: =F187
A39: TOTAL ASSETS | C39: =SUM(C27,C28,C29,C30,C31,C33,C34,C35,C36,C37,C38) | D39: =SUM(D27,D28,D29,D30,D31,D33,D34,D35,D36,D37,D38)
A42: Statement of Profit & Loss / Income & Expenditure / Revenue Account
...

Sheet C_IND
A1: Company — Ind AS — Schedule III Division II
A2: Authority: MCA | Official source: https://www.mca.gov.in/Ministry/pdf/ScheduleIIIAmendmentNotification_24032021.pdf
A3: =IF('AAH Basic Info'!B5="","","Address: "&'AAH Basic Info'!B5) | B3: =IF('AAH Basic Info'!B6="","","PAN: "&'AAH Basic Info'!B6) | C3: =IF('AAH Basic Info'!B7="","","GSTIN: "&'AAH Basic Info'!B7) | D3: =IF('AAH Basic Info'!B27="","",'AAH Basic Info'!B27)
A4: Entity Name | B4: Current Period | C4: Previous Period | D4: Presentation Unit | E4: Standalone / Consolidated
A5: =IF('AAH Basic Info'!B3="","",'AAH Basic Info'!B3) | B5: =IF('AAH Basic Info'!B9="","",'AAH Basic Info'!B9) | C5: =IF('AAH Basic Info'!B10="","",'AAH Basic Info'!B10) | D5: =IF('AAH Basic Info'!B24="","",'AAH Basic Info'!B24) | E5: =IF('AAH Basic Info'!B25="","",'AAH Basic Info'!B25)
A6: Balance Sheet / Statement of Financial Position
A7: Particulars | B7: Note No. | C7: Current Reporting Period | D7: Previous Reporting Period
A8: ASSETS
A9: 1. Non-current Assets
A10: Property, Plant and Equipment | B10: 1 | C10: =E83 | D10: =F83
A11: Capital Work-in-Progress | B11: 2 | C11: =E85 | D11: =F85
A12: Investment Property | B12: 3 | C12: =E87 | D12: =F87
A13: Goodwill | B13: 4 | C13: =E89 | D13: =F89
A14: Other Intangible Assets | B14: 5 | C14: =E91 | D14: =F91
A15: Intangible Assets under Development | B15: 6 | C15: =E93 | D15: =F93
A16: Biological Assets other than Bearer Plants | B16: 7 | C16: =E95 | D16: =F95
A17: Financial Assets - Investments | B17: 8 | C17: =E99 | D17: =F99
A18: Financial Assets - Trade Receivables | B18: 9 | C18: =E102 | D18: =F102
A19: Financial Assets - Loans | B19: 10 | C19: =E104 | D19: =F104
A20: Other Financial Assets | B20: 11 | C20: =E106 | D20: =F106
A21: Deferred Tax Assets (Net) | B21: 12 | C21: =E107 | D21: =F107
A22: Other Non-current Assets | B22: 13 | C22: =E111 | D22: =F111
A23: 2. Current Assets
A24: Inventories | B24: 14 | C24: =E117 | D24: =F117
A25: Financial Assets - Investments | B25: 8 | C25: =E99 | D25: =F99
A26: Financial Assets - Trade Receivables | B26: 9 | C26: =E102 | D26: =F102
A27: Cash and Cash Equivalents | B27: 16 | C27: =E124 | D27: =F124
A28: Bank Balances other than Cash Equivalents | B28: 17 | C28: =E126 | D28: =F126
A29: Financial Assets - Loans | B29: 10 | C29: =E104 | D29: =F104
A30: Other Financial Assets | B30: 11 | C30: =E106 | D30: =F106
A31: Current Tax Assets (Net) | B31: 15 | C31: =E118 | D31: =F118
A32: Other Current Assets | B32: 18 | C32: =E128 | D32: =F128
A33: TOTAL ASSETS | C33: =SUM(C10,C11,C12,C13,C14,C15,C16,C17,C18,C19,C20,C21,C22,C24,C25,C26,C27,C28,C29,C30,C31,C32) | D33: =SUM(D10,D11,D12,D13,D14,D15,D16,D17,D18,D19,D20,D21,D22,D24,D25,D26,D27,D28,D29,D30,D31,D32)
A34: EQUITY AND LIABILITIES
A35: Equity
A36: Equity Share Capital | B36: 19 | C36: =E130 | D36: =F130
A37: Other Equity | B37: 20 | C37: =E135 | D37: =F135
A38: Non-current Liabilities
A39: Financial Liabilities - Borrowings | B39: 21 | C39: =E137 | D39: =F137
A40: Trade Payables | B40: 22 | C40: =E140 | D40: =F140
...

Sheet NBFC_AS
A1: NBFC — Accounting Standards (non-Ind AS)
A2: Authority: MCA + RBI | Official source: https://www.rbi.org.in/
A3: =IF('AAH Basic Info'!B5="","","Address: "&'AAH Basic Info'!B5) | B3: =IF('AAH Basic Info'!B6="","","PAN: "&'AAH Basic Info'!B6) | C3: =IF('AAH Basic Info'!B7="","","GSTIN: "&'AAH Basic Info'!B7) | D3: =IF('AAH Basic Info'!B27="","",'AAH Basic Info'!B27)
A4: Entity Name | B4: Current Period | C4: Previous Period | D4: Presentation Unit | E4: Standalone / Consolidated
A5: =IF('AAH Basic Info'!B3="","",'AAH Basic Info'!B3) | B5: =IF('AAH Basic Info'!B9="","",'AAH Basic Info'!B9) | C5: =IF('AAH Basic Info'!B10="","",'AAH Basic Info'!B10) | D5: =IF('AAH Basic Info'!B24="","",'AAH Basic Info'!B24) | E5: =IF('AAH Basic Info'!B25="","",'AAH Basic Info'!B25)
A6: Balance Sheet / Statement of Financial Position
A7: Particulars | B7: Note No. | C7: Current Reporting Period | D7: Previous Reporting Period
A8: EQUITY AND LIABILITIES
A9: 1. Shareholders' Funds
A10: Share Capital | B10: 1 | C10: =E75 | D10: =F75
A11: Reserves and Surplus | B11: 2 | C11: =E83 | D11: =F83
A12: 2. Share Application Money Pending Allotment
A13: Share Application Money Pending Allotment | B13: —
A14: 3. Non-current Liabilities
A15: Long-term Borrowings | B15: 3 | C15: =E92 | D15: =F92
A16: Deferred Tax Liabilities (Net) | B16: 4 | C16: =E94 | D16: =F94
A17: Other Long-term Liabilities | B17: 5 | C17: =E98 | D17: =F98
A18: Long-term Provisions | B18: 6 | C18: =E101 | D18: =F101
A19: 4. Current Liabilities
A20: Short-term Borrowings | B20: 7 | C20: =E107 | D20: =F107
A21: Trade Payables | B21: 8 | C21: =E112 | D21: =F112
A22: Other Current Liabilities | B22: 9 | C22: =E121 | D22: =F121
A23: Short-term Provisions | B23: 10 | C23: =E125 | D23: =F125
A24: TOTAL EQUITY AND LIABILITIES | C24: =SUM(C10,C11,C13,C15,C16,C17,C18,C20,C21,C22,C23) | D24: =SUM(D10,D11,D13,D15,D16,D17,D18,D20,D21,D22,D23)
A25: ASSETS
A26: 1. Non-current Assets
A27: Property, Plant and Equipment / Intangibles / CWIP | B27: 11 | C27: =E135 | D27: =F135
A28: Non-current Investments | B28: 12 | C28: =E144 | D28: =F144
A29: Deferred Tax Assets (Net) | B29: 4 | C29: =E93 | D29: =F93
A30: Long-term Loans and Advances | B30: 13 | C30: =E150 | D30: =F150
A31: Other Non-current Assets | B31: 14 | C31: =E154 | D31: =F154
A32: 2. Current Assets
A33: Current Investments | B33: 15 | C33: =E158 | D33: =F158
A34: Inventories | B34: 16 | C34: =E167 | D34: =F167
A35: Trade Receivables | B35: 17 | C35: =E173 | D35: =F173
A36: Cash and Cash Equivalents | B36: 18 | C36: =E178 | D36: =F178
A37: Short-term Loans and Advances | B37: 19 | C37: =E182 | D37: =F182
A38: Other Current Assets | B38: 20 | C38: =E187 | D38: =F187
A39: TOTAL ASSETS | C39: =SUM(C27,C28,C29,C30,C31,C33,C34,C35,C36,C37,C38) | D39: =SUM(D27,D28,D29,D30,D31,D33,D34,D35,D36,D37,D38)
A42: Statement of Profit & Loss / Income & Expenditure / Revenue Account
...

Sheet NBFC_IND
A1: NBFC — Ind AS — Schedule III Division III
A2: Authority: MCA + RBI | Official source: https://www.mca.gov.in/Ministry/pdf/NotificationScheduleIII_12102018.pdf
A3: =IF('AAH Basic Info'!B5="","","Address: "&'AAH Basic Info'!B5) | B3: =IF('AAH Basic Info'!B6="","","PAN: "&'AAH Basic Info'!B6) | C3: =IF('AAH Basic Info'!B7="","","GSTIN: "&'AAH Basic Info'!B7) | D3: =IF('AAH Basic Info'!B27="","",'AAH Basic Info'!B27)
A4: Entity Name | B4: Current Period | C4: Previous Period | D4: Presentation Unit | E4: Standalone / Consolidated
A5: =IF('AAH Basic Info'!B3="","",'AAH Basic Info'!B3) | B5: =IF('AAH Basic Info'!B9="","",'AAH Basic Info'!B9) | C5: =IF('AAH Basic Info'!B10="","",'AAH Basic Info'!B10) | D5: =IF('AAH Basic Info'!B24="","",'AAH Basic Info'!B24) | E5: =IF('AAH Basic Info'!B25="","",'AAH Basic Info'!B25)
A6: Balance Sheet / Statement of Financial Position
A7: Particulars | B7: Note No. | C7: Current Reporting Period | D7: Previous Reporting Period
A8: ASSETS
A9: Financial Assets
A10: Cash and Cash Equivalents | B10: 1 | C10: =E82 | D10: =F82
A11: Bank Balance other than above | B11: 2 | C11: =E84 | D11: =F84
A12: Derivative Financial Instruments | B12: 3 | C12: =E87 | D12: =F87
A13: Receivables | B13: 4 | C13: =E90 | D13: =F90
A14: Loans | B14: 5 | C14: =E95 | D14: =F95
A15: Investments | B15: 6 | C15: =E100 | D15: =F100
A16: Other Financial Assets | B16: 7 | C16: =E102 | D16: =F102
A17: Non-financial Assets
A18: Inventories | B18: 8 | C18: =E104 | D18: =F104
A19: Current Tax Assets (Net) | B19: 9 | C19: =E105 | D19: =F105
A20: Deferred Tax Assets (Net) | B20: 10 | C20: =E108 | D20: =F108
A21: Investment Property | B21: 11 | C21: =E112 | D21: =F112
A22: Biological Assets other than Bearer Plants | B22: 12 | C22: =E114 | D22: =F114
A23: Property, Plant and Equipment | B23: 13 | C23: =E116 | D23: =F116
A24: Capital Work-in-Progress | B24: 14 | C24: =E118 | D24: =F118
A25: Intangible Assets under Development | B25: 15 | C25: =E120 | D25: =F120
A26: Goodwill | B26: 16 | C26: =E122 | D26: =F122
A27: Other Intangible Assets | B27: 17 | C27: =E124 | D27: =F124
A28: Other Non-financial Assets | B28: 18 | C28: =E126 | D28: =F126
A29: TOTAL ASSETS | C29: =SUM(C10,C11,C12,C13,C14,C15,C16,C18,C19,C20,C21,C22,C23,C24,C25,C26,C27,C28) | D29: =SUM(D10,D11,D12,D13,D14,D15,D16,D18,D19,D20,D21,D22,D23,D24,D25,D26,D27,D28)
A30: LIABILITIES AND EQUITY
A31: Financial Liabilities
A32: Derivative Financial Instruments | B32: 3 | C32: =E87 | D32: =F87
A33: Payables | B33: 19 | C33: =E129 | D33: =F129
A34: Debt Securities | B34: 20 | C34: =E131 | D34: =F131
A35: Borrowings (other than Debt Securities) | B35: 21 | C35: =E133 | D35: =F133
A36: Deposits | B36: 22 | C36: =E135 | D36: =F135
A37: Subordinated Liabilities | B37: 23 | C37: =E137 | D37: =F137
A38: Other Financial Liabilities | B38: 24 | C38: =E139 | D38: =F139
A39: Non-financial Liabilities
A40: Current Tax Liabilities (Net) | B40: 9 | C40: =E106 | D40: =F106
...

Sheet NCE
A1: Non-Corporate Entity
A2: Authority: ICAI | Official source: https://www.icai.org/post/guidance-notes
A3: =IF('AAH Basic Info'!B5="","","Address: "&'AAH Basic Info'!B5) | B3: =IF('AAH Basic Info'!B6="","","PAN: "&'AAH Basic Info'!B6) | C3: =IF('AAH Basic Info'!B7="","","GSTIN: "&'AAH Basic Info'!B7) | D3: =IF('AAH Basic Info'!B27="","",'AAH Basic Info'!B27)
A4: Entity Name | B4: Current Period | C4: Previous Period | D4: Presentation Unit | E4: Standalone / Consolidated
A5: =IF('AAH Basic Info'!B3="","",'AAH Basic Info'!B3) | B5: =IF('AAH Basic Info'!B9="","",'AAH Basic Info'!B9) | C5: =IF('AAH Basic Info'!B10="","",'AAH Basic Info'!B10) | D5: =IF('AAH Basic Info'!B24="","",'AAH Basic Info'!B24) | E5: =IF('AAH Basic Info'!B25="","",'AAH Basic Info'!B25)
A6: Balance Sheet / Statement of Financial Position
A7: Particulars | B7: Note No. | C7: Current Reporting Period | D7: Previous Reporting Period
A8: OWNERS' FUNDS AND LIABILITIES
A9: Owners' Funds
A10: Owners' / Partners' Capital Account | B10: 3a | C10: =E76 | D10: =F76
A11: Owners' / Partners' Current Account | B11: 3b | C11: =E81 | D11: =F81
A12: Reserves and Surplus | B12: 4 | C12: =E86 | D12: =F86
A13: Non-current Liabilities
A14: Long-term Borrowings | B14: 5 | C14: =E87+E88 | D14: =F87+F88
A15: Deferred Tax Liabilities (Net) | B15: 6 | C15: =E93 | D15: =F93
A16: Other Long-term Liabilities | B16: 7 | C16: =E96 | D16: =F96
A17: Long-term Provisions | B17: 8 | C17: =E97 | D17: =F97
A18: Current Liabilities
A19: Short-term Borrowings | B19: 5 | C19: =E89+E90 | D19: =F89+F90
A20: Trade Payables | B20: 9 | C20: =E102 | D20: =F102
A21: Other Current Liabilities | B21: 10 | C21: =E107 | D21: =F107
A22: Short-term Provisions | B22: 8 | C22: =E98 | D22: =F98
A23: TOTAL OWNERS' FUNDS AND LIABILITIES | C23: =SUM(C10,C11,C12,C14,C15,C16,C17,C19,C20,C21,C22) | D23: =SUM(D10,D11,D12,D14,D15,D16,D17,D19,D20,D21,D22)
A24: ASSETS
A25: Non-current Assets
A26: Property, Plant and Equipment / Intangibles / CWIP | B26: 11 | C26: =E112 | D26: =F112
A27: Non-current Investments | B27: 12 | C27: =E113 | D27: =F113
A28: Deferred Tax Assets (Net) | B28: 6 | C28: =E92 | D28: =F92
A29: Long-term Loans and Advances | B29: 13 | C29: =E116 | D29: =F116
A30: Other Non-current Assets | B30: 14 | C30: =E120 | D30: =F120
A31: Current Assets
A32: Current Investments | B32: 12 | C32: =E114 | D32: =F114
A33: Inventories | B33: 15 | C33: =E126 | D33: =F126
A34: Trade Receivables | B34: 16 | C34: =E130 | D34: =F130
A35: Cash and Bank Balances | B35: 17 | C35: =E134 | D35: =F134
A36: Short-term Loans and Advances | B36: 13 | C36: =E117 | D36: =F117
A37: Other Current Assets | B37: 18 | C37: =E138 | D37: =F138
A38: TOTAL ASSETS | C38: =SUM(C26,C27,C28,C29,C30,C32,C33,C34,C35,C36,C37) | D38: =SUM(D26,D27,D28,D29,D30,D32,D33,D34,D35,D36,D37)
A41: Statement of Profit & Loss / Income & Expenditure / Revenue Account
A42: Particulars | B42: Note No. | C42: Current Reporting Period | D42: Previous Reporting Period
...

Sheet LLP
A1: Limited Liability Partnership
A2: Authority: ICAI + MCA | Official source: https://www.icai.org/post/guidance-notes
A3: =IF('AAH Basic Info'!B5="","","Address: "&'AAH Basic Info'!B5) | B3: =IF('AAH Basic Info'!B6="","","PAN: "&'AAH Basic Info'!B6) | C3: =IF('AAH Basic Info'!B7="","","GSTIN: "&'AAH Basic Info'!B7) | D3: =IF('AAH Basic Info'!B27="","",'AAH Basic Info'!B27)
A4: Entity Name | B4: Current Period | C4: Previous Period | D4: Presentation Unit | E4: Standalone / Consolidated
A5: =IF('AAH Basic Info'!B3="","",'AAH Basic Info'!B3) | B5: =IF('AAH Basic Info'!B9="","",'AAH Basic Info'!B9) | C5: =IF('AAH Basic Info'!B10="","",'AAH Basic Info'!B10) | D5: =IF('AAH Basic Info'!B24="","",'AAH Basic Info'!B24) | E5: =IF('AAH Basic Info'!B25="","",'AAH Basic Info'!B25)
A6: Balance Sheet / Statement of Financial Position
A7: Particulars | B7: Note No. | C7: Current Reporting Period | D7: Previous Reporting Period
A8: PARTNERS' FUNDS AND LIABILITIES
A9: Partners' Contribution | B9: 3 | C9: =E68 | D9: =F68
A10: Partners' Current Accounts | B10: 4 | C10: =E70 | D10: =F70
A11: Reserves and Surplus | B11: 5 | C11: =E72 | D11: =F72
A12: Non-current Liabilities
A13: Long-term Borrowings | B13: 6 | C13: =E73 | D13: =F73
A14: Deferred Tax Liabilities (Net) | B14: 7 | C14: =E77 | D14: =F77
A15: Other Long-term Liabilities | B15: 8 | C15: =E79 | D15: =F79
A16: Long-term Provisions | B16: 9 | C16: =E82 | D16: =F82
A17: Current Liabilities
A18: Short-term Borrowings | B18: 6 | C18: =E74 | D18: =F74
A19: Trade Payables | B19: 10 | C19: =E87 | D19: =F87
A20: Other Current Liabilities | B20: 8 | C20: =E80 | D20: =F80
A21: Short-term Provisions | B21: 9 | C21: =E83 | D21: =F83
A22: TOTAL PARTNERS' FUNDS AND LIABILITIES | C22: =SUM(C9,C10,C11,C13,C14,C15,C16,C18,C19,C20,C21) | D22: =SUM(D9,D10,D11,D13,D14,D15,D16,D18,D19,D20,D21)
A23: ASSETS
A24: Non-current Assets
A25: PPE / Intangibles / CWIP | B25: 11 | C25: =E92 | D25: =F92
A26: Non-current Investments | B26: 12 | C26: =E93 | D26: =F93
A27: Deferred Tax Assets (Net) | B27: 7 | C27: =E76 | D27: =F76
A28: Long-term Loans and Advances | B28: 13 | C28: =E96 | D28: =F96
A29: Other Non-current Assets | B29: 14 | C29: =E100 | D29: =F100
A30: Current Assets
A31: Current Investments | B31: 12 | C31: =E94 | D31: =F94
A32: Inventories | B32: 15 | C32: =E102 | D32: =F102
A33: Trade Receivables | B33: 16 | C33: =E104 | D33: =F104
A34: Cash and Bank Balances | B34: 17 | C34: =E106 | D34: =F106
A35: Short-term Loans and Advances | B35: 13 | C35: =E97 | D35: =F97
A36: Other Current Assets | B36: 18 | C36: =E108 | D36: =F108
A37: TOTAL ASSETS | C37: =SUM(C25,C26,C27,C28,C29,C31,C32,C33,C34,C35,C36) | D37: =SUM(D25,D26,D27,D28,D29,D31,D32,D33,D34,D35,D36)
A40: Statement of Profit & Loss / Income & Expenditure / Revenue Account
A41: Particulars | B41: Note No. | C41: Current Reporting Period | D41: Previous Reporting Period
A42: Revenue from Operations | B42: 19 | C42: =E110 | D42: =F110
...

Sheet NPO
A1: Not-for-Profit Organisation
A2: Authority: ICAI / governing statute | Official source: https://www.icai.org/post/technical-guides-and-other-materials
A3: =IF('AAH Basic Info'!B5="","","Address: "&'AAH Basic Info'!B5) | B3: =IF('AAH Basic Info'!B6="","","PAN: "&'AAH Basic Info'!B6) | C3: =IF('AAH Basic Info'!B7="","","GSTIN: "&'AAH Basic Info'!B7) | D3: =IF('AAH Basic Info'!B27="","",'AAH Basic Info'!B27)
A4: Entity Name | B4: Current Period | C4: Previous Period | D4: Presentation Unit | E4: Standalone / Consolidated
A5: =IF('AAH Basic Info'!B3="","",'AAH Basic Info'!B3) | B5: =IF('AAH Basic Info'!B9="","",'AAH Basic Info'!B9) | C5: =IF('AAH Basic Info'!B10="","",'AAH Basic Info'!B10) | D5: =IF('AAH Basic Info'!B24="","",'AAH Basic Info'!B24) | E5: =IF('AAH Basic Info'!B25="","",'AAH Basic Info'!B25)
A6: Balance Sheet / Statement of Financial Position
A7: Particulars | B7: Note No. | C7: Current Reporting Period | D7: Previous Reporting Period
A8: FUNDS AND LIABILITIES
A9: Corpus / Capital Fund | B9: 1 | C9: =E46 | D9: =F46
A10: Restricted / Earmarked Funds | B10: 2 | C10: =E48 | D10: =F48
A11: Unrestricted / General Fund | B11: 3 | C11: =E50 | D11: =F50
A12: Secured / Unsecured Loans | B12: 4 | C12: =E53 | D12: =F53
A13: Deferred Credit Liabilities | B13: 5 | C13: =E55 | D13: =F55
A14: Current Liabilities and Provisions | B14: 6 | C14: =E58 | D14: =F58
A15: TOTAL FUNDS AND LIABILITIES | C15: =SUM(C9,C10,C11,C12,C13,C14) | D15: =SUM(D9,D10,D11,D12,D13,D14)
A16: ASSETS
A17: Fixed Assets / PPE | B17: 7 | C17: =E60 | D17: =F60
A18: Investments - Earmarked / Endowment Funds | B18: 8 | C18: =E62 | D18: =F62
A19: Other Investments | B19: 9 | C19: =E64 | D19: =F64
A20: Current Assets, Loans and Advances | B20: 10 | C20: =E67 | D20: =F67
A21: TOTAL ASSETS | C21: =SUM(C17,C18,C19,C20) | D21: =SUM(D17,D18,D19,D20)
A24: Income and Expenditure Account
A25: Particulars | B25: Note No. | C25: Current Reporting Period | D25: Previous Reporting Period
A26: INCOME
A27: Grants / Donations / Contributions | B27: 11 | C27: =E70 | D27: =F70
A28: Membership / Subscription Income | B28: 12 | C28: =E72 | D28: =F72
A29: Income from Investments | B29: 13 | C29: =E74 | D29: =F74
A30: Other Income | B30: 14 | C30: =E76 | D30: =F76
A31: TOTAL INCOME | C31: =SUM(C27,C28,C29,C30) | D31: =SUM(D27,D28,D29,D30)
A32: EXPENDITURE
A33: Programme / Project Expenses | B33: 15 | C33: =E78 | D33: =F78
A34: Employee Costs | B34: 16 | C34: =E80 | D34: =F80
A35: Administrative Expenses | B35: 17 | C35: =E82 | D35: =F82
A36: Finance Costs | B36: 18 | C36: =E84 | D36: =F84
A37: Depreciation / Amortisation | B37: 19 | C37: =E86 | D37: =F86
A38: Other Expenses | B38: 20 | C38: =E88 | D38: =F88
A39: TOTAL EXPENDITURE | C39: =SUM(C33,C34,C35,C36,C37,C38) | D39: =SUM(D33,D34,D35,D36,D37,D38)
A40: Surplus / (Deficit) for the Year | C40: =C31-C39 | D40: =D31-D39
A43: Notes / Schedules — linked source for face statements
A44: Note | B44: Note Title | C44: Statutory Line Item | D44: AAH Mapping Key | E44: Current Period | F44: Previous Period | G44: Disclosure / Remarks
...

Sheet BANK
A1: Banking Company
A2: Authority: RBI / Banking Regulation Act | Official source: https://www.indiacode.nic.in/bitstream/123456789/1885/1/A194910.pdf
A3: =IF('AAH Basic Info'!B5="","","Address: "&'AAH Basic Info'!B5) | B3: =IF('AAH Basic Info'!B6="","","PAN: "&'AAH Basic Info'!B6) | C3: =IF('AAH Basic Info'!B7="","","GSTIN: "&'AAH Basic Info'!B7) | D3: =IF('AAH Basic Info'!B27="","",'AAH Basic Info'!B27)
A4: Entity Name | B4: Current Period | C4: Previous Period | D4: Presentation Unit | E4: Standalone / Consolidated
A5: =IF('AAH Basic Info'!B3="","",'AAH Basic Info'!B3) | B5: =IF('AAH Basic Info'!B9="","",'AAH Basic Info'!B9) | C5: =IF('AAH Basic Info'!B10="","",'AAH Basic Info'!B10) | D5: =IF('AAH Basic Info'!B24="","",'AAH Basic Info'!B24) | E5: =IF('AAH Basic Info'!B25="","",'AAH Basic Info'!B25)
A6: Form A — Balance Sheet
A7: Particulars | B7: Schedule | C7: Current Reporting Period | D7: Previous Reporting Period
A8: CAPITAL AND LIABILITIES
A9: Capital | B9: 1 | C9: =E47 | D9: =F47
A10: Reserves and Surplus | B10: 2 | C10: =E53 | D10: =F53
A11: Deposits | B11: 3 | C11: =E57 | D11: =F57
A12: Borrowings | B12: 4 | C12: =E60 | D12: =F60
A13: Other Liabilities and Provisions | B13: 5 | C13: =E66 | D13: =F66
A14: TOTAL CAPITAL AND LIABILITIES | C14: =SUM(C9,C10,C11,C12,C13) | D14: =SUM(D9,D10,D11,D12,D13)
A15: ASSETS
A16: Cash and Balances with Reserve Bank of India | B16: 6 | C16: =E69 | D16: =F69
A17: Balances with Banks and Money at Call and Short Notice | B17: 7 | C17: =E73 | D17: =F73
A18: Investments | B18: 8 | C18: =E80 | D18: =F80
A19: Advances | B19: 9 | C19: =E85 | D19: =F85
A20: Fixed Assets | B20: 10 | C20: =E89 | D20: =F89
A21: Other Assets | B21: 11 | C21: =E96 | D21: =F96
A22: TOTAL ASSETS | C22: =SUM(C16,C17,C18,C19,C20,C21) | D22: =SUM(D16,D17,D18,D19,D20,D21)
A23: CONTINGENT LIABILITIES
A24: Contingent Liabilities | B24: 12 | C24: =E103 | D24: =F103
A27: Form B — Profit and Loss Account
A28: Particulars | B28: Schedule | C28: Current Reporting Period | D28: Previous Reporting Period
A29: INCOME
A30: Interest Earned | B30: 13 | C30: =E108 | D30: =F108
A31: Other Income | B31: 14 | C31: =E114 | D31: =F114
A32: TOTAL INCOME | C32: =SUM(C30,C31) | D32: =SUM(D30,D31)
A33: EXPENDITURE
A34: Interest Expended | B34: 15 | C34: =E118 | D34: =F118
A35: Operating Expenses | B35: 16 | C35: =E131 | D35: =F131
A36: Provisions and Contingencies | B36: —
A37: TOTAL EXPENDITURE | C37: =SUM(C34,C35) | D37: =SUM(D34,D35)
A38: Profit / (Loss) before Tax | C38: =C32-C37 | D38: =D32-D37
A39: Tax | B39: —
A40: Net Profit / (Loss) | C40: =C38-SUM(C39) | D40: =D38-SUM(D39)
A43: Notes / Schedules — linked source for face statements
A44: Note | B44: Note Title | C44: Statutory Line Item | D44: AAH Mapping Key | E44: Current Period | F44: Previous Period | G44: Disclosure / Remarks
...

Sheet COOPBANK
A1: Co-operative Bank
A2: Authority: RBI / Banking Regulation Act as adapted | Official source: https://www.rbi.org.in/
A3: =IF('AAH Basic Info'!B5="","","Address: "&'AAH Basic Info'!B5) | B3: =IF('AAH Basic Info'!B6="","","PAN: "&'AAH Basic Info'!B6) | C3: =IF('AAH Basic Info'!B7="","","GSTIN: "&'AAH Basic Info'!B7) | D3: =IF('AAH Basic Info'!B27="","",'AAH Basic Info'!B27)
A4: Entity Name | B4: Current Period | C4: Previous Period | D4: Presentation Unit | E4: Standalone / Consolidated
A5: =IF('AAH Basic Info'!B3="","",'AAH Basic Info'!B3) | B5: =IF('AAH Basic Info'!B9="","",'AAH Basic Info'!B9) | C5: =IF('AAH Basic Info'!B10="","",'AAH Basic Info'!B10) | D5: =IF('AAH Basic Info'!B24="","",'AAH Basic Info'!B24) | E5: =IF('AAH Basic Info'!B25="","",'AAH Basic Info'!B25)
A6: Form A — Balance Sheet
A7: Particulars | B7: Schedule | C7: Current Reporting Period | D7: Previous Reporting Period
A8: CAPITAL AND LIABILITIES
A9: Capital | B9: 1 | C9: =E47 | D9: =F47
A10: Reserves and Surplus | B10: 2 | C10: =E53 | D10: =F53
A11: Deposits | B11: 3 | C11: =E57 | D11: =F57
A12: Borrowings | B12: 4 | C12: =E60 | D12: =F60
A13: Other Liabilities and Provisions | B13: 5 | C13: =E66 | D13: =F66
A14: TOTAL CAPITAL AND LIABILITIES | C14: =SUM(C9,C10,C11,C12,C13) | D14: =SUM(D9,D10,D11,D12,D13)
A15: ASSETS
A16: Cash and Balances with Reserve Bank of India | B16: 6 | C16: =E69 | D16: =F69
A17: Balances with Banks and Money at Call and Short Notice | B17: 7 | C17: =E73 | D17: =F73
A18: Investments | B18: 8 | C18: =E80 | D18: =F80
A19: Advances | B19: 9 | C19: =E85 | D19: =F85
A20: Fixed Assets | B20: 10 | C20: =E89 | D20: =F89
A21: Other Assets | B21: 11 | C21: =E96 | D21: =F96
A22: TOTAL ASSETS | C22: =SUM(C16,C17,C18,C19,C20,C21) | D22: =SUM(D16,D17,D18,D19,D20,D21)
A23: CONTINGENT LIABILITIES
A24: Contingent Liabilities | B24: 12 | C24: =E103 | D24: =F103
A27: Form B — Profit and Loss Account
A28: Particulars | B28: Schedule | C28: Current Reporting Period | D28: Previous Reporting Period
A29: INCOME
A30: Interest Earned | B30: 13 | C30: =E108 | D30: =F108
A31: Other Income | B31: 14 | C31: =E114 | D31: =F114
A32: TOTAL INCOME | C32: =SUM(C30,C31) | D32: =SUM(D30,D31)
A33: EXPENDITURE
A34: Interest Expended | B34: 15 | C34: =E118 | D34: =F118
A35: Operating Expenses | B35: 16 | C35: =E131 | D35: =F131
A36: Provisions and Contingencies | B36: —
A37: TOTAL EXPENDITURE | C37: =SUM(C34,C35) | D37: =SUM(D34,D35)
A38: Profit / (Loss) before Tax | C38: =C32-C37 | D38: =D32-D37
A39: Tax | B39: —
A40: Net Profit / (Loss) | C40: =C38-SUM(C39) | D40: =D38-SUM(D39)
A43: Notes / Schedules — linked source for face statements
A44: Note | B44: Note Title | C44: Statutory Line Item | D44: AAH Mapping Key | E44: Current Period | F44: Previous Period | G44: Disclosure / Remarks
...

Sheet LIFE
A1: Life Insurance
A2: Authority: IRDAI | Official source: https://irdai.gov.in/
A3: =IF('AAH Basic Info'!B5="","","Address: "&'AAH Basic Info'!B5) | B3: =IF('AAH Basic Info'!B6="","","PAN: "&'AAH Basic Info'!B6) | C3: =IF('AAH Basic Info'!B7="","","GSTIN: "&'AAH Basic Info'!B7) | D3: =IF('AAH Basic Info'!B27="","",'AAH Basic Info'!B27)
A4: Entity Name | B4: Current Period | C4: Previous Period | D4: Presentation Unit | E4: Standalone / Consolidated
A5: =IF('AAH Basic Info'!B3="","",'AAH Basic Info'!B3) | B5: =IF('AAH Basic Info'!B9="","",'AAH Basic Info'!B9) | C5: =IF('AAH Basic Info'!B10="","",'AAH Basic Info'!B10) | D5: =IF('AAH Basic Info'!B24="","",'AAH Basic Info'!B24) | E5: =IF('AAH Basic Info'!B25="","",'AAH Basic Info'!B25)
A6: Form A-BS — Life Insurance Balance Sheet
A7: Particulars | B7: Schedule | C7: Current Reporting Period | D7: Previous Reporting Period
A8: SOURCES OF FUNDS
A9: Share Capital | B9: 1 | C9: =E51 | D9: =F51
A10: Reserves and Surplus | B10: 2 | C10: =E56 | D10: =F56
A11: Borrowings | B11: 3 | C11: =E58 | D11: =F58
A12: Policy Liabilities / Mathematical Reserves | B12: 12 | C12: =E77 | D12: =F77
A13: TOTAL SOURCES OF FUNDS | C13: =SUM(C9,C10,C11,C12) | D13: =SUM(D9,D10,D11,D12)
A14: APPLICATION OF FUNDS
A15: Investments - Shareholders | B15: 4 | C15: =E60 | D15: =F60
A16: Investments - Policyholders | B16: 5 | C16: =E62 | D16: =F62
A17: Loans | B17: 6 | C17: =E64 | D17: =F64
A18: Fixed Assets | B18: 7 | C18: =E66 | D18: =F66
A19: Cash and Bank Balances | B19: 8 | C19: =E68 | D19: =F68
A20: Advances and Other Assets | B20: 9 | C20: =E71 | D20: =F71
A21: Current Liabilities | B21: 10 | C21: =E73 | D21: =F73
A22: Provisions | B22: 11 | C22: =E75 | D22: =F75
A23: Fair Value Change Account | B23: 13 | C23: =E79 | D23: =F79
A24: Other / Miscellaneous Assets | B24: 14 | C24: =E81 | D24: =F81
A25: TOTAL APPLICATION OF FUNDS | C25: =SUM(C15,C16,C17,C18,C19,C20,C21,C22,C23,C24) | D25: =SUM(D15,D16,D17,D18,D19,D20,D21,D22,D23,D24)
A28: Policyholders' Revenue Account / Shareholders' Profit and Loss Account
A29: Particulars | B29: Schedule | C29: Current Reporting Period | D29: Previous Reporting Period
A30: POLICYHOLDERS' REVENUE ACCOUNT
A31: Premium Earned / Net | B31: 15 | C31: =E83 | D31: =F83
A32: Income from Investments | B32: 16 | C32: =E85 | D32: =F85
A33: Other Income | B33: —
A34: Commission | B34: 17 | C34: =E87 | D34: =F87
A35: Operating Expenses | B35: 18 | C35: =E89 | D35: =F89
A36: Benefits Paid | B36: 19 | C36: =E91 | D36: =F91
A37: Change in Valuation of Liability | B37: 20 | C37: =E93 | D37: =F93
A38: Surplus / (Deficit) | C38: =0 | D38: =0
A39: SHAREHOLDERS' PROFIT AND LOSS ACCOUNT
A40: Transfer from Policyholders' Account | B40: —
A41: Investment Income - Shareholders | B41: 16 | C41: =E85 | D41: =F85
A42: Other Income | B42: —
...

Sheet GENINS
A1: General Insurance
A2: Authority: IRDAI | Official source: https://irdai.gov.in/
A3: =IF('AAH Basic Info'!B5="","","Address: "&'AAH Basic Info'!B5) | B3: =IF('AAH Basic Info'!B6="","","PAN: "&'AAH Basic Info'!B6) | C3: =IF('AAH Basic Info'!B7="","","GSTIN: "&'AAH Basic Info'!B7) | D3: =IF('AAH Basic Info'!B27="","",'AAH Basic Info'!B27)
A4: Entity Name | B4: Current Period | C4: Previous Period | D4: Presentation Unit | E4: Standalone / Consolidated
A5: =IF('AAH Basic Info'!B3="","",'AAH Basic Info'!B3) | B5: =IF('AAH Basic Info'!B9="","",'AAH Basic Info'!B9) | C5: =IF('AAH Basic Info'!B10="","",'AAH Basic Info'!B10) | D5: =IF('AAH Basic Info'!B24="","",'AAH Basic Info'!B24) | E5: =IF('AAH Basic Info'!B25="","",'AAH Basic Info'!B25)
A6: Form B-BS — Balance Sheet
A7: Particulars | B7: Schedule | C7: Current Reporting Period | D7: Previous Reporting Period
A8: SOURCES OF FUNDS
A9: Share Capital | B9: 1 | C9: =E48 | D9: =F48
A10: Reserves and Surplus | B10: 2 | C10: =E50 | D10: =F50
A11: Borrowings | B11: 3 | C11: =E52 | D11: =F52
A12: TOTAL SOURCES OF FUNDS | C12: =SUM(C9,C10,C11) | D12: =SUM(D9,D10,D11)
A13: APPLICATION OF FUNDS
A14: Investments | B14: 4 | C14: =E54 | D14: =F54
A15: Loans | B15: 5 | C15: =E56 | D15: =F56
A16: Fixed Assets | B16: 6 | C16: =E58 | D16: =F58
A17: Cash and Bank Balances | B17: 7 | C17: =E60 | D17: =F60
A18: Advances and Other Assets | B18: 8 | C18: =E62 | D18: =F62
A19: Current Liabilities | B19: 9 | C19: =E64 | D19: =F64
A20: Provisions | B20: 10 | C20: =E66 | D20: =F66
A21: Fair Value Change Account | B21: 11 | C21: =E68 | D21: =F68
A22: Insurance / Regulatory Reserves | B22: 18 | C22: =E82 | D22: =F82
A23: TOTAL APPLICATION OF FUNDS | C23: =SUM(C14,C15,C16,C17,C18,C19,C20,C21,C22) | D23: =SUM(D14,D15,D16,D17,D18,D19,D20,D21,D22)
A26: Revenue Account / Profit and Loss Account
A27: Particulars | B27: Schedule | C27: Current Reporting Period | D27: Previous Reporting Period
A28: REVENUE ACCOUNT
A29: Premium Earned (Net) | B29: 12 | C29: =E70 | D29: =F70
A30: Claims Incurred (Net) | B30: 13 | C30: =E72 | D30: =F72
A31: Commission | B31: 14 | C31: =E74 | D31: =F74
A32: Operating Expenses | B32: 15 | C32: =E76 | D32: =F76
A33: Investment Income | B33: 16 | C33: =E78 | D33: =F78
A34: Other Income | B34: 17 | C34: =E80 | D34: =F80
A35: Operating Profit / (Loss) | C35: =0 | D35: =0
A36: PROFIT AND LOSS ACCOUNT
A37: Transfer from Revenue Accounts | B37: —
A38: Investment Income | B38: 16 | C38: =E78 | D38: =F78
A39: Other Income | B39: 17 | C39: =E80 | D39: =F80
A40: Other Expenses / Provisions | B40: —
A41: Tax | B41: —
A42: Profit / (Loss) | C42: =C35-SUM(C37,C38,C39,C40,C41) | D42: =D35-SUM(D37,D38,D39,D40,D41)
...

Sheet REINS
A1: Reinsurance
A2: Authority: IRDAI | Official source: https://irdai.gov.in/
A3: =IF('AAH Basic Info'!B5="","","Address: "&'AAH Basic Info'!B5) | B3: =IF('AAH Basic Info'!B6="","","PAN: "&'AAH Basic Info'!B6) | C3: =IF('AAH Basic Info'!B7="","","GSTIN: "&'AAH Basic Info'!B7) | D3: =IF('AAH Basic Info'!B27="","",'AAH Basic Info'!B27)
A4: Entity Name | B4: Current Period | C4: Previous Period | D4: Presentation Unit | E4: Standalone / Consolidated
A5: =IF('AAH Basic Info'!B3="","",'AAH Basic Info'!B3) | B5: =IF('AAH Basic Info'!B9="","",'AAH Basic Info'!B9) | C5: =IF('AAH Basic Info'!B10="","",'AAH Basic Info'!B10) | D5: =IF('AAH Basic Info'!B24="","",'AAH Basic Info'!B24) | E5: =IF('AAH Basic Info'!B25="","",'AAH Basic Info'!B25)
A6: Form B-BS — Balance Sheet
A7: Particulars | B7: Schedule | C7: Current Reporting Period | D7: Previous Reporting Period
A8: SOURCES OF FUNDS
A9: Share Capital | B9: 1 | C9: =E48 | D9: =F48
A10: Reserves and Surplus | B10: 2 | C10: =E50 | D10: =F50
A11: Borrowings | B11: 3 | C11: =E52 | D11: =F52
A12: TOTAL SOURCES OF FUNDS | C12: =SUM(C9,C10,C11) | D12: =SUM(D9,D10,D11)
A13: APPLICATION OF FUNDS
A14: Investments | B14: 4 | C14: =E54 | D14: =F54
A15: Loans | B15: 5 | C15: =E56 | D15: =F56
A16: Fixed Assets | B16: 6 | C16: =E58 | D16: =F58
A17: Cash and Bank Balances | B17: 7 | C17: =E60 | D17: =F60
A18: Advances and Other Assets | B18: 8 | C18: =E62 | D18: =F62
A19: Current Liabilities | B19: 9 | C19: =E64 | D19: =F64
A20: Provisions | B20: 10 | C20: =E66 | D20: =F66
A21: Fair Value Change Account | B21: 11 | C21: =E68 | D21: =F68
A22: Insurance / Regulatory Reserves | B22: 18 | C22: =E82 | D22: =F82
A23: TOTAL APPLICATION OF FUNDS | C23: =SUM(C14,C15,C16,C17,C18,C19,C20,C21,C22) | D23: =SUM(D14,D15,D16,D17,D18,D19,D20,D21,D22)
A26: Revenue Account / Profit and Loss Account
A27: Particulars | B27: Schedule | C27: Current Reporting Period | D27: Previous Reporting Period
A28: REVENUE ACCOUNT
A29: Premium Earned (Net) | B29: 12 | C29: =E70 | D29: =F70
A30: Claims Incurred (Net) | B30: 13 | C30: =E72 | D30: =F72
A31: Commission | B31: 14 | C31: =E74 | D31: =F74
A32: Operating Expenses | B32: 15 | C32: =E76 | D32: =F76
A33: Investment Income | B33: 16 | C33: =E78 | D33: =F78
A34: Other Income | B34: 17 | C34: =E80 | D34: =F80
A35: Operating Profit / (Loss) | C35: =0 | D35: =0
A36: PROFIT AND LOSS ACCOUNT
A37: Transfer from Revenue Accounts | B37: —
A38: Investment Income | B38: 16 | C38: =E78 | D38: =F78
A39: Other Income | B39: 17 | C39: =E80 | D39: =F80
A40: Other Expenses / Provisions | B40: —
A41: Tax | B41: —
A42: Profit / (Loss) | C42: =C35-SUM(C37,C38,C39,C40,C41) | D42: =D35-SUM(D37,D38,D39,D40,D41)
...

Sheet MF
A1: Mutual Fund Scheme
A2: Authority: SEBI | Official source: https://www.sebi.gov.in/legal/regulations/jul-2026/securities-and-exchange-board-of-india-mutual-funds-regulations-2026-last-amended-on-july-7-2026-_102780.html
A3: =IF('AAH Basic Info'!B5="","","Address: "&'AAH Basic Info'!B5) | B3: =IF('AAH Basic Info'!B6="","","PAN: "&'AAH Basic Info'!B6) | C3: =IF('AAH Basic Info'!B7="","","GSTIN: "&'AAH Basic Info'!B7) | D3: =IF('AAH Basic Info'!B27="","",'AAH Basic Info'!B27)
A4: Entity Name | B4: Current Period | C4: Previous Period | D4: Presentation Unit | E4: Standalone / Consolidated
A5: =IF('AAH Basic Info'!B3="","",'AAH Basic Info'!B3) | B5: =IF('AAH Basic Info'!B9="","",'AAH Basic Info'!B9) | C5: =IF('AAH Basic Info'!B10="","",'AAH Basic Info'!B10) | D5: =IF('AAH Basic Info'!B24="","",'AAH Basic Info'!B24) | E5: =IF('AAH Basic Info'!B25="","",'AAH Basic Info'!B25)
A6: Scheme-wise Balance Sheet
A7: Particulars | B7: Note No. | C7: Current Reporting Period | D7: Previous Reporting Period
A8: LIABILITIES
A9: Unit Capital | B9: 1 | C9: =E41 | D9: =F41
A10: Reserves and Surplus | B10: 2 | C10: =E43 | D10: =F43
A11: Current Liabilities and Provisions | B11: 10 | C11: =E62 | D11: =F62
A12: TOTAL LIABILITIES | C12: =SUM(C9,C10,C11) | D12: =SUM(D9,D10,D11)
A13: ASSETS
A14: Investments - Equity Shares | B14: 3 | C14: =E45 | D14: =F45
A15: Investments - Preference Shares | B15: 4 | C15: =E47 | D15: =F47
A16: Investments - Debentures / Bonds | B16: 5 | C16: =E49 | D16: =F49
A17: Investments - Government Securities | B17: 6 | C17: =E51 | D17: =F51
A18: Investments - Money Market Instruments | B18: 7 | C18: =E53 | D18: =F53
A19: Other Investments | B19: 8 | C19: =E55 | D19: =F55
A20: Current Assets | B20: 9 | C20: =E59 | D20: =F59
A21: TOTAL ASSETS | C21: =SUM(C14,C15,C16,C17,C18,C19,C20) | D21: =SUM(D14,D15,D16,D17,D18,D19,D20)
A24: Scheme-wise Revenue Account
A25: Particulars | B25: Note No. | C25: Current Reporting Period | D25: Previous Reporting Period
A26: REVENUE ACCOUNT
A27: Investment Income | B27: 11 | C27: =E64 | D27: =F64
A28: Profit / Loss on Sale of Investments | B28: 12 | C28: =E66 | D28: =F66
A29: Unrealised Appreciation / Depreciation | B29: 13 | C29: =E68 | D29: =F68
A30: Management Fees | B30: 14 | C30: =E70 | D30: =F70
A31: Trustee / Custodian / Other Expenses | B31: 15 | C31: =E72 | D31: =F72
A32: Surplus / (Deficit) | C32: =0 | D32: =0
A35: Notes / Schedules — linked source for face statements
A36: Note | B36: Note Title | C36: Statutory Line Item | D36: AAH Mapping Key | E36: Current Period | F36: Previous Period | G36: Disclosure / Remarks
A37: 1 | B37: Unit Capital | C37: Opening unit capital | D37: MF_UNIT_OPEN | E37: 0 | F37: 0
A38: 1 | B38: Unit Capital | C38: Units issued | D38: MF_UNIT_ISS | E38: 0 | F38: 0
A39: 1 | B39: Unit Capital | C39: Units redeemed | D39: MF_UNIT_RED | E39: 0 | F39: 0
A40: 1 | B40: Unit Capital | C40: Closing unit capital | D40: MF_UNIT_CLOSE | E40: 0 | F40: 0
A41: 1 | B41: Unit Capital | C41: Total — Unit Capital | D41: __TOTAL__ | E41: =SUM(E37:E40) | F41: =SUM(F37:F40)
A42: 2 | B42: Reserves and Surplus | C42: Reserves and surplus | D42: MF_RES | E42: 0 | F42: 0
A43: 2 | B43: Reserves and Surplus | C43: Total — Reserves and Surplus | D43: __TOTAL__ | E43: =SUM(E42:E42) | F43: =SUM(F42:F42)
A44: 3 | B44: Investments - Equity Shares | C44: Equity shares | D44: MF_INV_EQ | E44: 0 | F44: 0
...

Sheet CIS
A1: Collective Investment Scheme
A2: Authority: SEBI | Official source: https://www.sebi.gov.in/acts/cisreg.html
A3: =IF('AAH Basic Info'!B5="","","Address: "&'AAH Basic Info'!B5) | B3: =IF('AAH Basic Info'!B6="","","PAN: "&'AAH Basic Info'!B6) | C3: =IF('AAH Basic Info'!B7="","","GSTIN: "&'AAH Basic Info'!B7) | D3: =IF('AAH Basic Info'!B27="","",'AAH Basic Info'!B27)
A4: Entity Name | B4: Current Period | C4: Previous Period | D4: Presentation Unit | E4: Standalone / Consolidated
A5: =IF('AAH Basic Info'!B3="","",'AAH Basic Info'!B3) | B5: =IF('AAH Basic Info'!B9="","",'AAH Basic Info'!B9) | C5: =IF('AAH Basic Info'!B10="","",'AAH Basic Info'!B10) | D5: =IF('AAH Basic Info'!B24="","",'AAH Basic Info'!B24) | E5: =IF('AAH Basic Info'!B25="","",'AAH Basic Info'!B25)
A6: Scheme-wise Balance Sheet
A7: Particulars | B7: Note No. | C7: Current Reporting Period | D7: Previous Reporting Period
A8: ASSETS
A9: Fixed Assets | B9: 1 | C9: =E36 | D9: =F36
A10: Investments | B10: 2 | C10: =E38 | D10: =F38
A11: Project / Development Expenditure | B11: 3 | C11: =E40 | D11: =F40
A12: Current Assets | B12: 4 | C12: =E42 | D12: =F42
A13: Deferred Revenue Expenditure | B13: 5 | C13: =E44 | D13: =F44
A14: TOTAL ASSETS | C14: =SUM(C9,C10,C11,C12,C13) | D14: =SUM(D9,D10,D11,D12,D13)
A15: LIABILITIES
A16: Unit / Scheme Capital | B16: 6 | C16: =E46 | D16: =F46
A17: Reserves / Surplus | B17: 7 | C17: =E48 | D17: =F48
A18: Current Liabilities and Provisions | B18: 8 | C18: =E51 | D18: =F51
A19: TOTAL LIABILITIES | C19: =SUM(C16,C17,C18) | D19: =SUM(D16,D17,D18)
A22: Scheme-wise Revenue Account
A23: Particulars | B23: Note No. | C23: Current Reporting Period | D23: Previous Reporting Period
A24: REVENUE ACCOUNT
A25: Scheme Income | B25: 9 | C25: =E53 | D25: =F53
A26: Project / Scheme Operating Expenses | B26: 10 | C26: =E55 | D26: =F55
A27: Management / Trustee Expenses | B27: 11 | C27: =E57 | D27: =F57
A28: Depreciation | B28: 12 | C28: =E59 | D28: =F59
A29: Other Expenses | B29: 13 | C29: =E61 | D29: =F61
A30: Surplus / (Deficit) | C30: =0 | D30: =0
A33: Notes / Schedules — linked source for face statements
A34: Note | B34: Note Title | C34: Statutory Line Item | D34: AAH Mapping Key | E34: Current Period | F34: Previous Period | G34: Disclosure / Remarks
A35: 1 | B35: Fixed Assets | C35: Fixed assets | D35: CIS_FA | E35: 0 | F35: 0
A36: 1 | B36: Fixed Assets | C36: Total — Fixed Assets | D36: __TOTAL__ | E36: =SUM(E35:E35) | F36: =SUM(F35:F35)
A37: 2 | B37: Investments | C37: Investments | D37: CIS_INV | E37: 0 | F37: 0
A38: 2 | B38: Investments | C38: Total — Investments | D38: __TOTAL__ | E38: =SUM(E37:E37) | F38: =SUM(F37:F37)
A39: 3 | B39: Project / Development Expenditure | C39: Project / development expenditure | D39: CIS_DEV | E39: 0 | F39: 0
A40: 3 | B40: Project / Development Expenditure | C40: Total — Project / Development Expenditure | D40: __TOTAL__ | E40: =SUM(E39:E39) | F40: =SUM(F39:F39)
A41: 4 | B41: Current Assets | C41: Current assets | D41: CIS_CA | E41: 0 | F41: 0
A42: 4 | B42: Current Assets | C42: Total — Current Assets | D42: __TOTAL__ | E42: =SUM(E41:E41) | F42: =SUM(F41:F41)
A43: 5 | B43: Deferred Revenue Expenditure | C43: Deferred revenue expenditure | D43: CIS_DRE | E43: 0 | F43: 0
A44: 5 | B44: Deferred Revenue Expenditure | C44: Total — Deferred Revenue Expenditure | D44: __TOTAL__ | E44: =SUM(E43:E43) | F44: =SUM(F43:F43)
...

Sheet REIT
A1: Real Estate Investment Trust
A2: Authority: SEBI | Official source: https://www.sebi.gov.in/web/?file=https%3A%2F%2Fwww.sebi.gov.in%2Fsebi_data%2Fattachdocs%2Fmay-2025%2F1746617164275.pdf
A3: =IF('AAH Basic Info'!B5="","","Address: "&'AAH Basic Info'!B5) | B3: =IF('AAH Basic Info'!B6="","","PAN: "&'AAH Basic Info'!B6) | C3: =IF('AAH Basic Info'!B7="","","GSTIN: "&'AAH Basic Info'!B7) | D3: =IF('AAH Basic Info'!B27="","",'AAH Basic Info'!B27)
A4: Entity Name | B4: Current Period | C4: Previous Period | D4: Presentation Unit | E4: Standalone / Consolidated
A5: =IF('AAH Basic Info'!B3="","",'AAH Basic Info'!B3) | B5: =IF('AAH Basic Info'!B9="","",'AAH Basic Info'!B9) | C5: =IF('AAH Basic Info'!B10="","",'AAH Basic Info'!B10) | D5: =IF('AAH Basic Info'!B24="","",'AAH Basic Info'!B24) | E5: =IF('AAH Basic Info'!B25="","",'AAH Basic Info'!B25)
A6: Statement of Assets and Liabilities / Balance Sheet
A7: Particulars | B7: Note No. | C7: Current Reporting Period | D7: Previous Reporting Period
A8: ASSETS
A9: Investment Property / Infrastructure Assets | B9: 3 | C9: =E48 | D9: =F48
A10: Property, Plant and Equipment | B10: 4 | C10: =E50 | D10: =F50
A11: Investments in SPVs / HoldCos | B11: 5 | C11: =E52 | D11: =F52
A12: Other Financial Assets | B12: 6 | C12: =E54 | D12: =F54
A13: Cash and Bank Balances | B13: 7 | C13: =E56 | D13: =F56
A14: Other Assets | B14: 8 | C14: =E58 | D14: =F58
A15: TOTAL ASSETS | C15: =SUM(C9,C10,C11,C12,C13,C14) | D15: =SUM(D9,D10,D11,D12,D13,D14)
A16: EQUITY AND LIABILITIES
A17: Unit Capital | B17: 1 | C17: =E44 | D17: =F44
A18: Other Equity / Reserves | B18: 2 | C18: =E46 | D18: =F46
A19: Borrowings / Debt Securities | B19: 9 | C19: =E60 | D19: =F60
A20: Trade and Other Payables | B20: 10 | C20: =E62 | D20: =F62
A21: Other Financial Liabilities | B21: 11 | C21: =E64 | D21: =F64
A22: Other Liabilities / Provisions | B22: 12 | C22: =E66 | D22: =F66
A23: TOTAL EQUITY AND LIABILITIES | C23: =SUM(C17,C18,C19,C20,C21,C22) | D23: =SUM(D17,D18,D19,D20,D21,D22)
A26: Statement of Profit and Loss
A27: Particulars | B27: Note No. | C27: Current Reporting Period | D27: Previous Reporting Period
A28: Revenue from Operations | B28: 13 | C28: =E68 | D28: =F68
A29: Other Income | B29: 14 | C29: =E70 | D29: =F70
A30: TOTAL INCOME | C30: =SUM(C28,C29) | D30: =SUM(D28,D29)
A31: EXPENSES
A32: Finance Costs | B32: 15 | C32: =E72 | D32: =F72
A33: Operating / Property Expenses | B33: 16 | C33: =E74 | D33: =F74
A34: Manager / Employee Fees | B34: 17 | C34: =E76 | D34: =F76
A35: Depreciation / Amortisation | B35: 18 | C35: =E78 | D35: =F78
A36: Other Expenses | B36: 19 | C36: =E80 | D36: =F80
A37: TOTAL EXPENSES | C37: =SUM(C32,C33,C34,C35,C36) | D37: =SUM(D32,D33,D34,D35,D36)
A38: Profit / (Loss) for the Period | C38: =C30-C37 | D38: =D30-D37
A41: Notes / Schedules — linked source for face statements
A42: Note | B42: Note Title | C42: Statutory Line Item | D42: AAH Mapping Key | E42: Current Period | F42: Previous Period | G42: Disclosure / Remarks
A43: 1 | B43: Unit Capital | C43: Unit capital | D43: UNIT_CAP | E43: 0 | F43: 0
A44: 1 | B44: Unit Capital | C44: Total — Unit Capital | D44: __TOTAL__ | E44: =SUM(E43:E43) | F44: =SUM(F43:F43)
...

Sheet INVIT
A1: Infrastructure Investment Trust
A2: Authority: SEBI | Official source: https://www.sebi.gov.in/sebi_data/attachdocs/jul-2025/1752576381910.pdf
A3: =IF('AAH Basic Info'!B5="","","Address: "&'AAH Basic Info'!B5) | B3: =IF('AAH Basic Info'!B6="","","PAN: "&'AAH Basic Info'!B6) | C3: =IF('AAH Basic Info'!B7="","","GSTIN: "&'AAH Basic Info'!B7) | D3: =IF('AAH Basic Info'!B27="","",'AAH Basic Info'!B27)
A4: Entity Name | B4: Current Period | C4: Previous Period | D4: Presentation Unit | E4: Standalone / Consolidated
A5: =IF('AAH Basic Info'!B3="","",'AAH Basic Info'!B3) | B5: =IF('AAH Basic Info'!B9="","",'AAH Basic Info'!B9) | C5: =IF('AAH Basic Info'!B10="","",'AAH Basic Info'!B10) | D5: =IF('AAH Basic Info'!B24="","",'AAH Basic Info'!B24) | E5: =IF('AAH Basic Info'!B25="","",'AAH Basic Info'!B25)
A6: Statement of Assets and Liabilities / Balance Sheet
A7: Particulars | B7: Note No. | C7: Current Reporting Period | D7: Previous Reporting Period
A8: ASSETS
A9: Investment Property / Infrastructure Assets | B9: 3 | C9: =E48 | D9: =F48
A10: Property, Plant and Equipment | B10: 4 | C10: =E50 | D10: =F50
A11: Investments in SPVs / HoldCos | B11: 5 | C11: =E52 | D11: =F52
A12: Other Financial Assets | B12: 6 | C12: =E54 | D12: =F54
A13: Cash and Bank Balances | B13: 7 | C13: =E56 | D13: =F56
A14: Other Assets | B14: 8 | C14: =E58 | D14: =F58
A15: TOTAL ASSETS | C15: =SUM(C9,C10,C11,C12,C13,C14) | D15: =SUM(D9,D10,D11,D12,D13,D14)
A16: EQUITY AND LIABILITIES
A17: Unit Capital | B17: 1 | C17: =E44 | D17: =F44
A18: Other Equity / Reserves | B18: 2 | C18: =E46 | D18: =F46
A19: Borrowings / Debt Securities | B19: 9 | C19: =E60 | D19: =F60
A20: Trade and Other Payables | B20: 10 | C20: =E62 | D20: =F62
A21: Other Financial Liabilities | B21: 11 | C21: =E64 | D21: =F64
A22: Other Liabilities / Provisions | B22: 12 | C22: =E66 | D22: =F66
A23: TOTAL EQUITY AND LIABILITIES | C23: =SUM(C17,C18,C19,C20,C21,C22) | D23: =SUM(D17,D18,D19,D20,D21,D22)
A26: Statement of Profit and Loss
A27: Particulars | B27: Note No. | C27: Current Reporting Period | D27: Previous Reporting Period
A28: Revenue from Operations | B28: 13 | C28: =E68 | D28: =F68
A29: Other Income | B29: 14 | C29: =E70 | D29: =F70
A30: TOTAL INCOME | C30: =SUM(C28,C29) | D30: =SUM(D28,D29)
A31: EXPENSES
A32: Finance Costs | B32: 15 | C32: =E72 | D32: =F72
A33: Operating / Property Expenses | B33: 16 | C33: =E74 | D33: =F74
A34: Manager / Employee Fees | B34: 17 | C34: =E76 | D34: =F76
A35: Depreciation / Amortisation | B35: 18 | C35: =E78 | D35: =F78
A36: Other Expenses | B36: 19 | C36: =E80 | D36: =F80
A37: TOTAL EXPENSES | C37: =SUM(C32,C33,C34,C35,C36) | D37: =SUM(D32,D33,D34,D35,D36)
A38: Profit / (Loss) for the Period | C38: =C30-C37 | D38: =D30-D37
A41: Notes / Schedules — linked source for face statements
A42: Note | B42: Note Title | C42: Statutory Line Item | D42: AAH Mapping Key | E42: Current Period | F42: Previous Period | G42: Disclosure / Remarks
A43: 1 | B43: Unit Capital | C43: Unit capital | D43: UNIT_CAP | E43: 0 | F43: 0
A44: 1 | B44: Unit Capital | C44: Total — Unit Capital | D44: __TOTAL__ | E44: =SUM(E43:E43) | F44: =SUM(F43:F43)
...

Sheet 03_QA_Status
A1: AAH Financial Statement Library — QA Status
A3: Check | B3: Scope | C3: Result | D3: Evidence | E3: Action | F3: Status
A4: Profile coverage | B4: 16 statutory/regulatory profiles | C4: 16/16 present | D4: Index + profile sheets | E4: None | F4: PASS
A5: Face statements | B5: Balance Sheet + P&L/equivalent | C5: Present | D5: Each profile top section | E5: Review with real client data | F5: PASS
A6: Linked notes | B6: Face statements linked to note totals | C6: Present | D6: Formula links within profile sheet | E6: Populate mapping keys / disclosures | F6: PASS
A7: Comparatives | B7: Current + previous period columns | C7: Present | D7: All face statements and notes | E7: None | F7: PASS
A8: Special statements | B8: CFS/SOCE/NAV/NDCF where profile requires | C8: Present as structured blocks | D8: Profile special sections | E8: AAH calculation engine to populate | F8: PASS
A9: Formula integrity | B9: Workbook formula error scan | C9: No #REF/#DIV0/#VALUE/#NAME/#N/A | D9: Fresh import verification | E9: None | F9: PASS
A10: Visual presentation | B10: Company AS / NCE / Bank / REIT sampled | C10: Clean professional hierarchy | D10: Rendered previews | E10: Final print-area setup can be applied inside AAH export | F10: PASS
A11: AAH readiness | B11: Mapping keys embedded in note lines | C11: Ready for ledger mapping design | D11: AAH Mapping Key column | E11: Next phase: persistent ledger-to-key mapping | F11: PASS

Sheet AAH Basic Info
A1: AAH Financial Statements - Basic Information
A3: Entity Name
A4: Mailing Name
A5: Address
A6: PAN
A7: GSTIN
A8: Entity Type
A9: Current Year End
A10: Previous Year End
A11: Rounding
A12: PPE / FA Block
A13: Entity Signatory
... A30: CA Signing Date
